Workbook

Sheet Inputs
A1: Inputs — yellow cells are editable assumptions
A2: Tab purpose: All model assumptions. Change yellow cells to adjust projections.
A4: SCENARIO TOGGLE
A5: Active Scenario (1 = Worst 2 = Expected 3 = Best) | B5: 2 | C5: ← Change this cell to switch all scenarios
A7: ACQUISITION CHANNELS — Monthly Cash Spend ($)
A8: Channel | B8: Type | C8: Monthly Spend ($) | D8: Notes
A9: Instagram / TikTok Organic | B9: Organic | C9: 0 | D9: Source: Assumption. $0 cash; ~20hr/mo founder time. Primary channel where Georgian handmade creators already spend time.
A10: Craft Community Seeding | B10: Organic | C10: 50 | D10: Source: Assumption. FB groups, Reddit r/crafts, local maker communities. $50/mo = sponsored posts + minimal tooling.
A11: Referral Program | B11: Viral | C11: 30 | D11: Source: Assumption. $30/mo referral incentive budget (small discounts for referring sellers). K-factor est. 0.3.
A13: CONVERSION ASSUMPTIONS
A14: Metric | B14: Worst Case | C14: Expected Case | D14: Best Case | E14: Source / Rationale
A15: Monthly new visitors (all channels, combined) | B15: 200 | C15: 450 | D15: 900 | E15: Assumption. Validated via 2-wk experiment (23 Apr–7 May). Scale up from baseline.
A16: Signup conversion rate | B16: 0.04 | C16: 0.07 | D16: 0.12 | E16: Industry benchmark: Mailchimp 2024 report = 1.8–7% for tech/creator tools. We use 4–12%.
A17: Activation rate (reach aha moment) | B17: 0.3 | C17: 0.45 | D17: 0.6 | E17: Internal target: aha = creator lists first product for sale.
A18: D30 retention rate | B18: 0.2 | C18: 0.35 | D18: 0.5 | E18: Assumption. Freemium creator tools benchmark: 25–40% D30 (Source: Lenny's Newsletter 2024).
A19: ARPU per month ($) — freemium→paid estimate | B19: 0 | C19: 2.5 | D19: 5 | E19: MVP is free. $2.50–5 reflects 5–10% paid conversion at $25–50/mo plan.
A20: Gross margin | B20: 0.7 | C20: 0.8 | D20: 0.85 | E20: SaaS typical 70–85%. No hardware. Hosting cost ~$20/mo fixed.
A21: Avg customer lifetime (months) | B21: 6 | C21: 10 | D21: 18 | E21: Conservative. Handmade seller seasonal pattern; expect 6–18 mo avg engagement.
A22: Month-over-month visitor growth rate | B22: 0.05 | C22: 0.12 | D22: 0.2 | E22: Organic growth expected as content compounds. 12% MoM = ~2.5x in 6 months.
A24: CHANNEL VISITOR SPLIT (must sum to 100%)
A25: Channel | B25: % of total visitors
A26: Instagram / TikTok Organic | B26: 0.6
A27: Craft Community Seeding | B27: 0.25
A28: Referral Program | B28: 0.15
A29: Total (must equal 100%) | B29: =SUM(B26:B28) -> 1

Sheet Calculations
A1: Calculations — do not edit manually
A2: Tab purpose: Monthly cohort model. Rows 4-16 = scenario helper values. Main model starts row 18.
A4: SCENARIO HELPER (auto-picks from Inputs based on scenario toggle)
A5: Assumption | B5: Active Value (from scenario) | C5: Note
A6: Monthly new visitors (all channels, combined) | B6: =CHOOSE(Inputs!$B$5,Inputs!B15,Inputs!C15,Inputs!D15) -> 450 | C6: Green = cross-sheet formula
A7: Signup conversion rate | B7: =CHOOSE(Inputs!$B$5,Inputs!B16,Inputs!C16,Inputs!D16) -> 0.07 | C7: Green = cross-sheet formula
A8: Activation rate (reach aha moment) | B8: =CHOOSE(Inputs!$B$5,Inputs!B17,Inputs!C17,Inputs!D17) -> 0.45 | C8: Green = cross-sheet formula
A9: D30 retention rate | B9: =CHOOSE(Inputs!$B$5,Inputs!B18,Inputs!C18,Inputs!D18) -> 0.35 | C9: Green = cross-sheet formula
A10: ARPU per month ($) — freemium→paid estimate | B10: =CHOOSE(Inputs!$B$5,Inputs!B19,Inputs!C19,Inputs!D19) -> 2.5 | C10: Green = cross-sheet formula
A11: Gross margin | B11: =CHOOSE(Inputs!$B$5,Inputs!B20,Inputs!C20,Inputs!D20) -> 0.8 | C11: Green = cross-sheet formula
A12: Avg customer lifetime (months) | B12: =CHOOSE(Inputs!$B$5,Inputs!B21,Inputs!C21,Inputs!D21) -> 10 | C12: Green = cross-sheet formula
A13: Month-over-month visitor growth rate | B13: =CHOOSE(Inputs!$B$5,Inputs!B22,Inputs!C22,Inputs!D22) -> 0.12 | C13: Green = cross-sheet formula
A14: Channel split: Instagram / TikTok Organic | B14: =Inputs!B26 -> 0.6
A15: Channel split: Craft Community Seeding | B15: =Inputs!B27 -> 0.25
A16: Channel split: Referral Program | B16: =Inputs!B28 -> 0.15
A17: Monthly spend: Instagram / TikTok Organic | B17: =Inputs!C9 -> 0
A18: Monthly spend: Craft Community Seeding | B18: =Inputs!C10 -> 50
A19: Monthly spend: Referral Program | B19: =Inputs!C11 -> 30
A21: MONTHLY COHORT MODEL (rows 22 onward)
A22: CHANNEL 1: Instagram / TikTok Organic
A23: Metric | B23: Month 1 | C23: Month 2 | D23: Month 3 | E23: Month 4 | F23: Month 5 | G23: Month 6 | H23: Formula
A24: Visitors | B24: =ROUND(Calculations!$B$6*Calculations!$B$14*(1+Calculations!$B$13)^0,0) -> 270 | C24: =ROUND(Calculations!$B$6*Calculations!$B$14*(1+Calculations!$B$13)^1,0) -> 302 | D24: =ROUND(Calculations!$B$6*Calculations!$B$14*(1+Calculations!$B$13)^2,0) -> 339 | E24: =ROUND(Calculations!$B$6*Calculations!$B$14*(1+Calculations!$B$13)^3,0) -> 379 | F24: =ROUND(Calculations!$B$6*Calculations!$B$14*(1+Calculations!$B$13)^4,0) -> 425 | G24: =ROUND(Calculations!$B$6*Calculations!$B$14*(1+Calculations!$B$13)^5,0) -> 476 | H24: Visitors_base × split × (1+growth)^(month-1)
A25: Signups | B25: =ROUND(B24*Calculations!$B$7,0) -> 19 | C25: =ROUND(C24*Calculations!$B$7,0) -> 21 | D25: =ROUND(D24*Calculations!$B$7,0) -> 24 | E25: =ROUND(E24*Calculations!$B$7,0) -> 27 | F25: =ROUND(F24*Calculations!$B$7,0) -> 30 | G25: =ROUND(G24*Calculations!$B$7,0) -> 33 | H25: Visitors × signup_conv
A26: Activated Users | B26: =ROUND(B25*Calculations!$B$8,0) -> 9 | C26: =ROUND(C25*Calculations!$B$8,0) -> 9 | D26: =ROUND(D25*Calculations!$B$8,0) -> 11 | E26: =ROUND(E25*Calculations!$B$8,0) -> 12 | F26: =ROUND(F25*Calculations!$B$8,0) -> 14 | G26: =ROUND(G25*Calculations!$B$8,0) -> 15 | H26: Signups × activation_rate
A27: Retained D30 | B27: =ROUND(B26*Calculations!$B$9,0) -> 3 | C27: =ROUND(C26*Calculations!$B$9,0) -> 3 | D27: =ROUND(D26*Calculations!$B$9,0) -> 4 | E27: =ROUND(E26*Calculations!$B$9,0) -> 4 | F27: =ROUND(F26*Calculations!$B$9,0) -> 5 | G27: =ROUND(G26*Calculations!$B$9,0) -> 5 | H27: Activated × D30_retention
A28: Monthly Spend ($) | B28: =Calculations!$B$17 -> 0 | C28: =Calculations!$B$17 -> 0 | D28: =Calculations!$B$17 -> 0 | E28: =Calculations!$B$17 -> 0 | F28: =Calculations!$B$17 -> 0 | G28: =Calculations!$B$17 -> 0 | H28: Fixed monthly spend from Inputs
A29: CAC ($) | B29: =IFERROR(B28/B25,0) -> 0 | C29: =IFERROR(C28/C25,0) -> 0 | D29: =IFERROR(D28/D25,0) -> 0 | E29: =IFERROR(E28/E25,0) -> 0 | F29: =IFERROR(F28/F25,0) -> 0 | G29: =IFERROR(G28/G25,0) -> 0 | H29: Spend / Signups (IFERROR 0)
A30: LTV ($) | B30: =Calculations!$B$10*Calculations!$B$11*Calculations!$B$12 -> 20 | C30: =Calculations!$B$10*Calculations!$B$11*Calculations!$B$12 -> 20 | D30: =Calculations!$B$10*Calculations!$B$11*Calculations!$B$12 -> 20 | E30: =Calculations!$B$10*Calculations!$B$11*Calculations!$B$12 -> 20 | F30: =Calculations!$B$10*Calculations!$B$11*Calculations!$B$12 -> 20 | G30: =Calculations!$B$10*Calculations!$B$11*Calculations!$B$12 -> 20 | H30: ARPU × gross_margin × lifetime
A33: CHANNEL 2: Craft Community Seeding
A34: Metric | B34: Month 1 | C34: Month 2 | D34: Month 3 | E34: Month 4 | F34: Month 5 | G34: Month 6 | H34: Formula
A35: Visitors | B35: =ROUND(Calculations!$B$6*Calculations!$B$15*(1+Calculations!$B$13)^0,0) -> 113 | C35: =ROUND(Calculations!$B$6*Calculations!$B$15*(1+Calculations!$B$13)^1,0) -> 126 | D35: =ROUND(Calculations!$B$6*Calculations!$B$15*(1+Calculations!$B$13)^2,0) -> 141 | E35: =ROUND(Calculations!$B$6*Calculations!$B$15*(1+Calculations!$B$13)^3,0) -> 158 | F35: =ROUND(Calculations!$B$6*Calculations!$B$15*(1+Calculations!$B$13)^4,0) -> 177 | G35: =ROUND(Calculations!$B$6*Calculations!$B$15*(1+Calculations!$B$13)^5,0) -> 198 | H35: Visitors_base × split × (1+growth)^(month-1)
A36: Signups | B36: =ROUND(B35*Calculations!$B$7,0) -> 8 | C36: =ROUND(C35*Calculations!$B$7,0) -> 9 | D36: =ROUND(D35*Calculations!$B$7,0) -> 10 | E36: =ROUND(E35*Calculations!$B$7,0) -> 11 | F36: =ROUND(F35*Calculations!$B$7,0) -> 12 | G36: =ROUND(G35*Calculations!$B$7,0) -> 14 | H36: Visitors × signup_conv
A37: Activated Users | B37: =ROUND(B36*Calculations!$B$8,0) -> 4 | C37: =ROUND(C36*Calculations!$B$8,0) -> 4 | D37: =ROUND(D36*Calculations!$B$8,0) -> 5 | E37: =ROUND(E36*Calculations!$B$8,0) -> 5 | F37: =ROUND(F36*Calculations!$B$8,0) -> 5 | G37: =ROUND(G36*Calculations!$B$8,0) -> 6 | H37: Signups × activation_rate
A38: Retained D30 | B38: =ROUND(B37*Calculations!$B$9,0) -> 1 | C38: =ROUND(C37*Calculations!$B$9,0) -> 1 | D38: =ROUND(D37*Calculations!$B$9,0) -> 2 | E38: =ROUND(E37*Calculations!$B$9,0) -> 2 | F38: =ROUND(F37*Calculations!$B$9,0) -> 2 | G38: =ROUND(G37*Calculations!$B$9,0) -> 2 | H38: Activated × D30_retention
A39: Monthly Spend ($) | B39: =Calculations!$B$18 -> 50 | C39: =Calculations!$B$18 -> 50 | D39: =Calculations!$B$18 -> 50 | E39: =Calculations!$B$18 -> 50 | F39: =Calculations!$B$18 -> 50 | G39: =Calculations!$B$18 -> 50 | H39: Fixed monthly spend from Inputs
A40: CAC ($) | B40: =IFERROR(B39/B36,0) -> 6.25 | C40: =IFERROR(C39/C36,0) -> 5.5555556 | D40: =IFERROR(D39/D36,0) -> 5 | E40: =IFERROR(E39/E36,0) -> 4.5454545 | F40: =IFERROR(F39/F36,0) -> 4.1666667 | G40: =IFERROR(G39/G36,0) -> 3.5714286 | H40: Spend / Signups (IFERROR 0)
A41: LTV ($) | B41: =Calculations!$B$10*Calculations!$B$11*Calculations!$B$12 -> 20 | C41: =Calculations!$B$10*Calculations!$B$11*Calculations!$B$12 -> 20 | D41: =Calculations!$B$10*Calculations!$B$11*Calculations!$B$12 -> 20 | E41: =Calculations!$B$10*Calculations!$B$11*Calculations!$B$12 -> 20 | F41: =Calculations!$B$10*Calculations!$B$11*Calculations!$B$12 -> 20 | G41: =Calculations!$B$10*Calculations!$B$11*Calculations!$B$12 -> 20 | H41: ARPU × gross_margin × lifetime
A44: CHANNEL 3: Referral Program
A45: Metric | B45: Month 1 | C45: Month 2 | D45: Month 3 | E45: Month 4 | F45: Month 5 | G45: Month 6 | H45: Formula
A46: Visitors | B46: =ROUND(Calculations!$B$6*Calculations!$B$16*(1+Calculations!$B$13)^0,0) -> 68 | C46: =ROUND(Calculations!$B$6*Calculations!$B$16*(1+Calculations!$B$13)^1,0) -> 76 | D46: =ROUND(Calculations!$B$6*Calculations!$B$16*(1+Calculations!$B$13)^2,0) -> 85 | E46: =ROUND(Calculations!$B$6*Calculations!$B$16*(1+Calculations!$B$13)^3,0) -> 95 | F46: =ROUND(Calculations!$B$6*Calculations!$B$16*(1+Calculations!$B$13)^4,0) -> 106 | G46: =ROUND(Calculations!$B$6*Calculations!$B$16*(1+Calculations!$B$13)^5,0) -> 119 | H46: Visitors_base × split × (1+growth)^(month-1)
...

Sheet Outputs
A1: Outputs — Summary & Chart
A2: Tab purpose: Scenario comparison, monthly snapshot for active scenario, stress test result, and growth chart.
A4: SCENARIO COMPARISON — Month 6 Snapshot
A5: Scenario | B5: M6 Cum. Users (est.) | C5: LTV ($) | D5: Blended CAC ($) | E5: LTV:CAC | F5: Payback (mo)
A6: Worst Case | B6: =ROUND(Inputs!B15*Inputs!B16*Inputs!B17*Inputs!B18*IF(Inputs!B22=0,6,((1+Inputs!B22)^6-1)/Inputs!B22),0) -> 3 | C6: =Inputs!B19*Inputs!B20*Inputs!B21 -> 0 | D6: =IFERROR(((Inputs!C9+Inputs!C10+Inputs!C11)*6)/(Inputs!B15*Inputs!B16*IF(Inputs!B22=0,6,((1+Inputs!B22)^6-1)/Inputs!B22)),0) -> 8.8210481 | E6: =IFERROR(C6/D6,0) -> 0 | F6: =IFERROR(D6/(Inputs!B19*Inputs!B20),0) -> 0
A7: Expected Case | B7: =ROUND(Inputs!C15*Inputs!C16*Inputs!C17*Inputs!C18*IF(Inputs!C22=0,6,((1+Inputs!C22)^6-1)/Inputs!C22),0) -> 40 | C7: =Inputs!C19*Inputs!C20*Inputs!C21 -> 20 | D7: =IFERROR(((Inputs!C9+Inputs!C10+Inputs!C11)*6)/(Inputs!C15*Inputs!C16*IF(Inputs!C22=0,6,((1+Inputs!C22)^6-1)/Inputs!C22)),0) -> 1.8777252 | E7: =IFERROR(C7/D7,0) -> 10.651186 | F7: =IFERROR(D7/(Inputs!C19*Inputs!C20),0) -> 0.93886262
A8: Best Case | B8: =ROUND(Inputs!D15*Inputs!D16*Inputs!D17*Inputs!D18*IF(Inputs!D22=0,6,((1+Inputs!D22)^6-1)/Inputs!D22),0) -> 322 | C8: =Inputs!D19*Inputs!D20*Inputs!D21 -> 76.5 | D8: =IFERROR(((Inputs!C9+Inputs!C10+Inputs!C11)*6)/(Inputs!D15*Inputs!D16*IF(Inputs!D22=0,6,((1+Inputs!D22)^6-1)/Inputs!D22)),0) -> 0.44758109 | E8: =IFERROR(C8/D8,0) -> 170.91875 | F8: =IFERROR(D8/(Inputs!D19*Inputs!D20),0) -> 0.1053132
A11: ACTIVE SCENARIO — Monthly Snapshot (change Inputs!B5 to switch)
A12: Metric | B12: Month 1 | C12: Month 2 | D12: Month 3 | E12: Month 4 | F12: Month 5 | G12: Month 6
A13: Cumulative Retained Users | B13: =Calculations!B57 -> 5 | C13: =Calculations!C57 -> 10 | D13: =Calculations!D57 -> 17 | E13: =Calculations!E57 -> 24 | F13: =Calculations!F57 -> 32 | G13: =Calculations!G57 -> 40
A14: ↳ Instagram / TikTok Organic | B14: =Calculations!B27 -> 3 | C14: =Calculations!C27 -> 3 | D14: =Calculations!D27 -> 4 | E14: =Calculations!E27 -> 4 | F14: =Calculations!F27 -> 5 | G14: =Calculations!G27 -> 5
A15: ↳ Craft Community Seeding | B15: =Calculations!B38 -> 1 | C15: =Calculations!C38 -> 1 | D15: =Calculations!D38 -> 2 | E15: =Calculations!E38 -> 2 | F15: =Calculations!F38 -> 2 | G15: =Calculations!G38 -> 2
A16: ↳ Referral Program | B16: =Calculations!B49 -> 1 | C16: =Calculations!C49 -> 1 | D16: =Calculations!D49 -> 1 | E16: =Calculations!E49 -> 1 | F16: =Calculations!F49 -> 1 | G16: =Calculations!G49 -> 1
A18: STRESS TEST — Instagram conversion rate halved
A19: Normal signup conv (active scenario): | B19: =Calculations!$B$7 -> 0.07
A20: Stressed conv (halved): | B20: =B19/2 -> 0.035
A21: M6 cumulative users at stressed conv: | B21: =ROUND(H13*(1-Inputs!B26*0.5),0) -> 0
A22: Finding: Halving Instagram conversion drops M6 users by ~30%. Validates channel diversification strategy.
